Workbook

Sheet Sheet1
A1: grmc_comm_no | B1: Community Code | C1: Sector | D1: Community | E1: Total population | F1: Area km2 | G1: Population Density (person/km2) | H1: geom
A2: 1 | B2: 614 | C2: Sector 6 | D2: RAS AL KHOR IND. THIRD | E2: 28657 | F2: 5.448028 | G2: =E2/F2 -> 5260.0684 | H2: =VLOOKUP(A2,ref!$A$2:$C$220,2,0) -> POLYGON Z ((55.380157086628 25.1831863435418 0,55.3811986763899 25.182987410677 0,55.3822303457505 25.182797501013 0,55.3832719188949 25.1825985535579 0,55.384303591663 25.1824086294362 0,55.3852856484874 25.1822187155483 0,55.3862677061554 25.1820378223977 0,55.3872497609114 25.18185692273 0,55.3882318087066 25.1816669802636 0,55.3892138575695 25.1814860765897 0,55.3901959035155 25.1813051573721 0,55.391177942287 25.1811152043832 0,55.3921599922545 25.180934272129 0,55.3931420194674 25.1807533333667 0,55.3941240492084 25.1805633608296 0,55.395106080441 25.1803824090317 0,55.396088108759 25.1802014507184 0,55.3970701341621 25.1800204858897 0,55.3968415443173 25.1792081309619 0,55.3966823572741 25.1783145005621 0,55.3965231725674 25.1774208698787 0,55.3963639901969 25.1765272389116 0,55.3962048101626 25.1756336076609 0,55.3960456278455 25.1747309488649 0,55.3959760497591 25.1744601604083 0,55.3958368853062 25.1739005288396 0,55.3956977221297 25.1733408970953 0,55.3955387305558 25.1727812735102 0,55.3953797251688 25.1722306769825 0,55.3952108114275 25.1716800843832 0,55.3950319750023 25.1711204684158 0,55.3948432296566 25.1705789108433 0,55.3946544814681 25.1700283257196 0,55.3940386186149 25.1683133980958 0,55.3936214474798 25.1671851594969 0,55.3932936765056 25.1663006197724 0,55.3929758338649 25.165425102486 0,55.392648076644 25.1645495883795 0,55.3923104050548 25.1636740773869 0,55.3919826572887 25.1627985615832 0,55.3916549142142 25.161923044942 0,55.3911087102782 25.1605150032664 0,55.3901468496046 25.1610840941727 0,55.3891948988948 25.1616531750608 0,55.3882330203998 25.1622222534782 0,55.3879355123687 25.1623577636592 0,55.3874594901917 25.1625565476172 0,55.3869834664652 25.1627553210148 0,55.3865074372791 25.1629450656015 0,55.3860214837213 25.1631257849076 0,55.385535524886 25.1632974753392 0,55.3850495646874 25.163469164174 0,55.3840082066889 25.1638125608338 0,55.3829767619475 25.164155946837 0,55.3819353922893 25.1644993289038 0,55.3808940167877 25.1648427036389 0,55.3802890208071 25.1650324695731 0,55.379674100351 25.165213208862 0,55.3790591747121 25.1653849183193 0,55.3784442473471 25.165556625221 0,55.3780078512736 25.1656650848663 0,55.3774226556538 25.1658277512704 0,55.3767382989255 25.1659994627136 0,55.3760539335078 25.1661802163245 0,55.3753695598755 25.1663429031927 0,55.3746752620866 25.1664965623914 0,55.3739908818569 25.1666502156092 0,55.3732965776489 25.1667948410655 0,55.3726022689074 25.1669304359901 0,55.3718980364486 25.1670570029675 0,55.3712037218788 25.1671835640575 0,55.3700630482906 25.1673553696804 0,55.3689124521187 25.1675271688982 0,55.3677717721005 25.167698956866 0,55.3666211694716 25.1678707382748 0,55.3658574137082 25.1680153444327 0,55.3661155550461 25.1688999603479 0,55.3663737001163 25.1697845757035 0,55.3666318612907 25.1706782177679 0,55.3668900039258 25.1715628320052 0,55.3671481627038 25.1724564729491 0,55.3674063227442 25.1733410860635 0,55.3676644890465 25.1742347258843 0,55.3679226565735 25.1751193378778 0,55.3681907504635 25.1760129742394 0,55.3684489255497 25.1768975850943 0,55.3687071069761 25.1777912226509 0,55.368965289551 25.1786758323845 0,55.3692234758611 25.1795604415578 0,55.3694816685696 25.1804540774293 0,55.3697398524495 25.1813386854833 0,55.3699980626048 25.1822323112011 0,55.3702562638992 25.183116927158 0,55.3710701815385 25.1844978918442 0,55.3708421342093 25.18492223076 0,55.371873836023 25.1847323933093 0,55.3729154553819 25.1845425460106 0,55.373947147773 25.1843436668487 0,55.3749887605933 25.1841538049534 0,55.3760204463242 25.183954911334 0,55.3770521319157 25.1837650377742 0,55.3780937316738 25.1835661267667 0,55.3791254107557 25.1833762387508 0,55.380157086628 25.1831863435418 0))
A3: 2 | B3: 975 | C3: Sector 9 | D3: AL O'SHOOSH | E3: 3 | F3: 58.948906 | G3: =E3/F3 -> 0.05089153 | H3: =VLOOKUP(A3,ref!$A$2:$C$220,2,0) -> POLYGON Z ((55.4011538721935 24.7222664107786 0,55.4011963886216 24.6972820049993 0,55.3544696063453 24.6484390356853 0,55.3583104879215 24.6265492781151 0,55.3583105372543 24.6265490343528 0,55.334563552928 24.6230788337961 0,55.3238503938412 24.6260035811611 0,55.3238503963102 24.6260035822898 0,55.3238502678699 24.6260042413207 0,55.3238502654009 24.626004240192 0,55.3076765977224 24.7058414966691 0,55.3355662808459 24.7058436733758 0,55.4011538721935 24.7222664107786 0))
A4: 3 | B4: 988 | C4: Sector 9 | D4: AL LAYAN 2 | E4: 0 | F4: 36.997665 | G4: =E4/F4 -> 0 | H4: =VLOOKUP(A4,ref!$A$2:$C$220,2,0) -> POLYGON Z ((55.2028350521651 24.7328676863636 0,55.1490335234094 24.7180174018429 0,55.1427562974278 24.724944485077 0,55.1102821790244 24.7640676997626 0,55.1358615706748 24.7745118824641 0,55.1614693498445 24.784949739853 0,55.2028350521651 24.7328676863636 0))
A5: 4 | B5: 241 | C5: Sector 2 | D5: AL NAHDA SECOND | E5: 71100 | F5: 2.2115706 | G5: =E5/F5 -> 32149.098 | H5: =VLOOKUP(A5,ref!$A$2:$C$220,2,0) -> POLYGON Z ((55.38842208342 25.2957254203803 0,55.3878259132795 25.2948680656832 0,55.3872297555226 25.2940197355806 0,55.3866336060695 25.2931714029573 0,55.3860374649198 25.2923230678138 0,55.3854413420022 25.2914747301466 0,55.3848452037144 25.2906173628447 0,55.3843087010264 25.2898592707984 0,55.3837722050148 25.2891011767127 0,55.3832357119849 25.2883340534627 0,55.3827091584817 25.2875759519752 0,55.3821726788634 25.2868088337078 0,55.3816362095679 25.2860507224737 0,55.3811096723457 25.2852835878845 0,55.3805732163807 25.2845254816362 0,55.3800367670896 25.2837673733499 0,55.3795102498002 25.2830002327869 0,55.3789638783967 25.282224069265 0,55.3784175106149 25.2814388764945 0,55.3775737581493 25.2819356242972 0,55.3767200668968 25.2824233430376 0,55.375876300696 25.2829200720589 0,55.3750225957597 25.2834077899583 0,55.37417881583 25.2839045182511 0,55.3733250972034 25.2843922172541 0,55.3724813035413 25.2848889357901 0,55.3716275712275 25.2853766249224 0,55.3707837638328 25.2858733337001 0,55.3699300178315 25.2863610129605 0,55.3690861967041 25.2868577119787 0,55.367855177209 25.2875079584384 0,55.3666340737436 25.2881581923419 0,55.3672399662489 25.2889253601532 0,55.3678557956722 25.2896925230651 0,55.3684617060946 25.2904687128073 0,55.3690676215888 25.2912358728477 0,55.3698820854229 25.2920751957725 0,55.3706965533095 25.2929235412159 0,55.3715110495651 25.2937628549268 0,55.3724247919098 25.2944396496127 0,55.3733286146649 25.2951164412568 0,55.3742423772375 25.2957932155075 0,55.3751561499596 25.2964700020769 0,55.3763479157953 25.296993232099 0,55.3775297619231 25.2975164554168 0,55.3779071486773 25.2976517485807 0,55.3783639924619 25.2978050707681 0,55.379218039847 25.2980214583033 0,55.3800919324543 25.2981656176769 0,55.3801217258591 25.298174635343 0,55.3811445421799 25.2982465242407 0,55.3812934955264 25.2982555029939 0,55.3822467634051 25.298228108588 0,55.3825943019219 25.2982009115773 0,55.3834680735307 25.298038129093 0,55.3843318826254 25.2978031279597 0,55.3851658579501 25.2974959153319 0,55.3859700358362 25.2971345459262 0,55.3867344479186 25.2967009696009 0,55.3867443738228 25.296691938891 0,55.3875782650317 25.2962041703 0,55.38842208342 25.2957254203803 0))
A6: 5 | B6: 978 | C6: Sector 9 | D6: SAIH SHUA'ALAH | E6: 0 | F6: 69.543181 | G6: =E6/F6 -> 0 | H6: =VLOOKUP(A6,ref!$A$2:$C$220,2,0) -> POLYGON Z ((55.4012056868235 24.6918175490864 0,55.4632910862367 24.6917767186409 0,55.4966018107694 24.64667774301 0,55.4966020276933 24.6466774448543 0,55.4867450113768 24.6452471030772 0,55.4096041193467 24.6340312379803 0,55.3583105372543 24.6265490343528 0,55.3583104879215 24.6265492781151 0,55.3544696063453 24.6484390356853 0,55.4011963886216 24.6972820049993 0,55.4012056868235 24.6918175490864 0))
A7: 6 | B7: 214 | C7: Sector 2 | D7: AL GARHOUD | E7: 22216 | F7: 4.0428636 | G7: =E7/F7 -> 5495.1149 | H7: =VLOOKUP(A7,ref!$A$2:$C$220,2,0) -> POLYGON Z ((55.3690331597278 25.2413157174406 0,55.3682290408437 25.2407381697137 0,55.367424929558 25.2401606175566 0,55.3666208258707 25.2395830609697 0,55.3658167297815 25.2390054999534 0,55.3650126412926 25.2384279435352 0,55.3641986353209 25.2378503667076 0,55.3632258034609 25.2371374187371 0,55.3622430579874 25.2364244662243 0,55.3612603260383 25.2357205342878 0,55.3603173087757 25.2350346428789 0,55.3593643773017 25.2343487471279 0,55.3584213812557 25.2336628434744 0,55.3575975188368 25.2331123311793 0,55.3567736621035 25.2325527780212 0,55.3559498129102 25.231993220222 0,55.3550267048754 25.2313163097901 0,55.3541135330882 25.2306484283534 0,55.3532003698093 25.2299715140077 0,55.352605018839 25.2307027959745 0,55.3519997348139 25.2314250495309 0,55.3514043695866 25.2321563265249 0,55.3508089959476 25.2328785738557 0,55.3502136152749 25.2336008187209 0,55.3498762232559 25.2339619446787 0,55.3491914978785 25.2346029505542 0,55.3486754563063 25.2349911743699 0,55.3481296390123 25.235397453735 0,55.3475739020519 25.2357947048266 0,55.345896679735 25.2367427121247 0,55.3452019639424 25.2370858028328 0,55.3446759657896 25.2373837414498 0,55.3439713327859 25.2378983346913 0,55.3429094163033 25.2387559993746 0,55.341996354903 25.2394962852028 0,55.3410733577416 25.2402455930244 0,55.3401602740896 25.2409858673612 0,55.3397533843292 25.2419156857436 0,55.3393564134161 25.2428364753009 0,55.3389495109645 25.2437572640555 0,55.3385426027663 25.2446870787574 0,55.3381456137286 25.2456078647186 0,55.3377386932515 25.2465376769749 0,55.337331766286 25.2474584608154 0,55.3370836420117 25.2481806415688 0,55.33670649682 25.249615971766 0,55.3364980882476 25.2510874058989 0,55.336468347556 25.2525588357602 0,55.3365974274535 25.2539941532154 0,55.3368059108804 25.2550232458272 0,55.3370243243781 25.2560523377531 0,55.3374412336631 25.2558717833817 0,55.3382948971574 25.2554023444047 0,55.339138627194 25.2549238736851 0,55.3399922775365 25.2544544248378 0,55.3408459213156 25.2539849710273 0,55.3416896321815 25.253515512816 0,55.342543262872 25.2530460491376 0,55.3433968869992 25.252576580497 0,55.3442504946369 25.2521071068952 0,55.3450941893666 25.2516376291213 0,55.3459477938421 25.2511681456534 0,55.3471090801192 25.2505090581808 0,55.348260428913 25.2498589897025 0,55.3492430363886 25.249308229406 0,55.3502355622133 25.2487664885766 0,55.3512181519912 25.2482157150674 0,55.3522007329079 25.2476649440125 0,55.3531833064259 25.2471231755091 0,55.3541162515122 25.2466355795272 0,55.3550591148992 25.2461479761657 0,55.3559920450462 25.2456603682814 0,55.3569249677414 25.2451727454507 0,55.3581358336578 25.2448475776096 0,55.3593466950408 25.2445314179873 0,55.3605476225448 25.2442062230782 0,55.3616393728783 25.2439261752673 0,55.3627211948239 25.2436551485383 0,55.3638129352359 25.2433750846511 0,55.3648947451331 25.2430950148104 0,55.3661452177564 25.2425711657222 0,55.3671376512844 25.2421647186853 0,55.3681201553807 25.2417672944871 0,55.3690331597278 25.2413157174406 0))
A8: 7 | B8: 363 | C8: Sector 3 | D8: AL MANARA | E8: 9838 | F8: 2.1945596 | G8: =E8/F8 -> 4482.9039 | H8: =VLOOKUP(A8,ref!$A$2:$C$220,2,0) -> POLYGON Z ((55.2143813263652 25.1339472953113 0,55.2142427034915 25.1337305286613 0,55.2134290202643 25.1342624834638 0,55.2126153388717 25.1347854064381 0,55.2118016416243 25.1353173521767 0,55.2109879373366 25.1358492933825 0,55.2101742260086 25.1363812300551 0,55.2093605076401 25.1369131621942 0,55.2085368653089 25.1374450814474 0,55.2077231328165 25.137977004464 0,55.2069093932833 25.1385089229461 0,55.2060956467092 25.1390408368934 0,55.2052819030111 25.1395727463142 0,55.2044681336763 25.1401046523119 0,55.2046266457126 25.1402582529783 0,55.2052109754652 25.1410080248651 0,55.2058052296143 25.1417578029366 0,55.2063895736819 25.1425075700797 0,55.206973924868 25.1432573438972 0,55.2075682006525 25.1440071057269 0,55.2081525569581 25.1447658930542 0,55.2087369296421 25.1455156507452 0,55.2093312171725 25.1462654143764 0,55.2099156041757 25.1470151673208 0,55.2105000181533 25.1477649089001 0,55.2110943273073 25.1485146743398 0,55.211787689361 25.1494089461906 0,55.2124810703966 25.1502941874486 0,55.2131843794561 25.1511794334378 0,55.2138777816742 25.1520736953034 0,55.2145216520125 25.1528866685844 0,55.2151556423889 25.1536996311181 0,55.2157995495411 25.154512598743 0,55.2159382330351 25.1546932543329 0,55.2167818304187 25.1541252019924 0,55.2176254114863 25.1535661720497 0,55.2184689848762 25.1530071372325 0,55.2193125589774 25.1524390702646 0,55.2201561169498 25.1518800256986 0,55.2209996672448 25.1513209762591 0,55.2218432098626 25.1507619219466 0,55.2226867529432 25.1501938354811 0,55.2239867695689 25.1493372086328 0,55.2234816845528 25.1485243789776 0,55.2229765980948 25.147720574817 0,55.2224715182388 25.1469167688695 0,55.2219664531755 25.1461039338501 0,55.2214613865589 25.1453001243285 0,55.2209563364604 25.144496313028 0,55.2204611988595 25.1436834801952 0,55.2199561520155 25.1428796653477 0,55.2194511018537 25.1420758487069 0,55.2189460865374 25.1412630030056 0,55.2184410595278 25.1404591828005 0,55.217936039125 25.1396553517829 0,55.2173220999478 25.1386799331028 0,55.2167180960408 25.1376954742423 0,55.2161041762945 25.1367200503275 0,55.2155595798969 25.1358529974857 0,55.2150149998707 25.1349769152725 0,55.2144704188585 25.13410985828 0,55.2143813263652 25.1339472953113 0))
A9: 8 | B9: 213 | C9: Sector 2 | D9: NADD SHAMMA | E9: 3648 | F9: 1.0929607 | G9: =E9/F9 -> 3337.7228 | H9: =VLOOKUP(A9,ref!$A$2:$C$220,2,0) -> POLYGON Z ((55.3856386228249 25.2189142948569 0,55.3865613506408 25.2185438498291 0,55.387484068863 25.218164371822 0,55.3883968619704 25.2177939189527 0,55.3893195729549 25.2174234566802 0,55.3902621209096 25.2170439537868 0,55.3911451527503 25.2167276586507 0,55.39255405107 25.2162757403118 0,55.3932287440869 25.2160858970158 0,55.3943102359015 25.215787556844 0,55.3943697710801 25.2157784960351 0,55.3944293062589 25.2157694532566 0,55.3944987692163 25.2157694245338 0,55.3945583088941 25.2157693998883 0,55.3946476274587 25.2157874172991 0,55.3946475867418 25.2157061723905 0,55.3946475505491 25.2156339546933 0,55.3946276452182 25.2155166091635 0,55.3945779340258 25.2153270582643 0,55.3945680017458 25.2153090079496 0,55.3945679927095 25.2152909535243 0,55.394329606326 25.2148126096852 0,55.3939819353001 25.2141086299025 0,55.3932568073958 25.2126013803443 0,55.3920561649302 25.2126921342644 0,55.3908555164188 25.2127738512202 0,55.3895060164762 25.2128465878372 0,55.3881664379534 25.2129193084589 0,55.3870451610723 25.2129829015546 0,55.3859238830166 25.2130465042024 0,55.3848025999778 25.2131010621039 0,55.3836813196375 25.2131646387196 0,55.3825600381162 25.2132282068329 0,55.3824905802178 25.2132372661882 0,55.3824012797679 25.2132553412614 0,55.3823119756779 25.2132643890636 0,55.3822226751889 25.2132824820832 0,55.3821234515882 25.2133005692967 0,55.3820341546341 25.2133276803922 0,55.3819448540539 25.2133457642169 0,55.3818654765338 25.2133638447306 0,55.381776179476 25.2133909556702 0,55.3816868823787 25.2134180665559 0,55.3815975852416 25.2134451773876 0,55.3815082880649 25.2134722881653 0,55.3814289139462 25.2134993956613 0,55.3813396202342 25.2135355335538 0,55.3812503229342 25.2135626441756 0,55.3811709522289 25.2135987787497 0,55.3810915814767 25.2136349132811 0,55.3810022875659 25.2136710509695 0,55.3809229167169 25.2137071854101 0,55.3808435458209 25.2137433198081 0,55.3807542552562 25.2137884845629 0,55.3806748842541 25.2138246098428 0,55.380595516699 25.2138697803509 0,55.3805260722132 25.2139149386218 0,55.380446704541 25.2139601000224 0,55.3803673368102 25.2140052613802 0,55.3802879690207 25.2140504226952 0,55.3802185277746 25.2141045990099 0,55.3801391598691 25.2141497692717 0,55.3800697185041 25.2142039545432 0,55.3800002770776 25.2142581397817 0,55.3799209124256 25.2143123281145 0,55.3798514708716 25.2143665132826 0,55.3797820292561 25.2144206984176 0,55.3789487450914 25.2150979991129 0,55.3781055085698 25.2157752980739 0,55.3772721959711 25.2164525892239 0,55.3759825176623 25.2174730421117 0,55.3758342277466 25.2190889558685 0,55.3761026244663 25.2204068512283 0,55.3763710269913 25.2217247458582 0,55.3763513001093 25.222067785509 0,55.3767878989109 25.22193224968 0,55.377998494861 25.2216430181645 0,55.3792090816846 25.2213447495231 0,55.3795266070918 25.2212543785487 0,55.3809455208309 25.2207935496939 0,55.3818980444694 25.2204140879984 0,55.3828505621926 25.2200346291815 0,55.383803073997 25.2196551642163 0,55.3847258129778 25.2192847306656 0,55.3856386228249 25.2189142948569 0))
A10: 9 | B10: 319 | C10: Sector 3 | D10: OUD METHA | E10: 17294 | F10: 1.5159583 | G10: =E10/F10 -> 11407.965 | H10: =VLOOKUP(A10,ref!$A$2:$C$220,2,0) -> POLYGON Z ((55.3167279734416 25.2306218658268 0,55.3165693103259 25.229683028201 0,55.3164106496438 25.2287441812596 0,55.315378435022 25.2293127731025 0,55.314346210803 25.2298813576866 0,55.3133239014626 25.2304499363553 0,55.3122420401571 25.2309914178211 0,55.3111700938365 25.2315328928093 0,55.3102867225863 25.2319841175391 0,55.3094033448184 25.2324353369559 0,55.308519962365 25.2328775238638 0,55.3076365617022 25.2333287326524 0,55.3067531743711 25.2337799361305 0,55.3058697705957 25.2342311433197 0,55.3049863603066 25.2346823271399 0,55.3050754603843 25.2356482538398 0,55.3051744748333 25.2366232094416 0,55.3052635856484 25.2375981629683 0,55.3059978520047 25.2384378292587 0,55.3067222052196 25.2392684718651 0,55.3074564916282 25.2401081307328 0,55.3081907899841 25.2409387496505 0,55.3089151711198 25.2417783994043 0,55.3095800269737 25.2425277641171 0,55.3102448926864 25.2432680985847 0,55.3109097647978 25.2440174571733 0,55.3115647194247 25.2447668112365 0,55.3122296077833 25.2455161637434 0,55.3128945042949 25.2462655222138 0,55.3135494846053 25.2470058310583 0,55.3142143973189 25.247755174419 0,55.3146611613174 25.2471052837673 0,55.3147902258631 25.2469157202455 0,55.3149192913674 25.2467171384541 0,55.3150384306711 25.2465185553153 0,55.3151377167134 25.2463289968101 0,55.3152469308702 25.2461213850896 0,55.3153462189239 25.2459137720738 0,55.3154355809237 25.2457061668102 0,55.3155150182407 25.2454895150547 0,55.3155547381064 25.2453721664914 0,55.3156143184163 25.2451916300325 0,55.315693760293 25.244938878468 0,55.3157632775068 25.2446770984902 0,55.3158228701059 25.2444062901121 0,55.3158327970082 25.2443972641066 0,55.3160810914492 25.2433050042123 0,55.3163293814452 25.2422127437368 0,55.3165776669967 25.2411204826802 0,55.3166671181907 25.240217774142 0,55.3167565680592 25.2393150654386 0,55.3168757980478 25.2383672239439 0,55.3169950249759 25.2374284094207 0,55.3171241762318 25.2364805685788 0,55.3172434005915 25.2355327264209 0,55.3173626230979 25.2345848840443 0,55.3173725738404 25.2343862868484 0,55.3172139009073 25.2334474413609 0,55.3170453057639 25.2325085944912 0,55.3168866377728 25.2315697484162 0,55.3167279734416 25.2306218658268 0))
A11: 10 | B11: 134 | C11: Sector 1 | D11: AL MAMZAR | E11: 23173 | F11: 5.7997838 | G11: =E11/F11 -> 3995.4938 | H11: =VLOOKUP(A11,ref!$A$2:$C$220,2,0) -> POLYGON Z ((55.348144096398 25.3133506160481 0,55.3482796646508 25.3133375943184 0,55.3482120836904 25.3127562436255 0,55.3480730191034 25.3127695996462 0,55.3480692164653 25.3126649996509 0,55.3479996983134 25.3126650065831 0,55.3479718733376 25.3126002399161 0,55.3478342195381 25.3122833572152 0,55.3477962144545 25.311709345753 0,55.3477658131122 25.3112709476206 0,55.347781709802 25.3108276522373 0,55.3477089638375 25.3103118688439 0,55.3476529984193 25.309852123999 0,55.3475925206792 25.3094420466587 0,55.3475628680104 25.3088554774058 0,55.3475590442988 25.3084273854457 0,55.3476116969871 25.3080840434841 0,55.3476623161694 25.3077627819832 0,55.3477360088613 25.3073970145715 0,55.3479535458627 25.3067703315061 0,55.3481838891917 25.3062091023272 0,55.3483186392052 25.3059764691848 0,55.3484841134375 25.3057394546116 0,55.3487291839469 25.3053714933635 0,55.3489932779353 25.3049883099674 0,55.3493260696284 25.3044546638275 0,55.3495761243645 25.3039696460455 0,55.3497587662378 25.3036081803555 0,55.3499342404202 25.3031239645858 0,55.3501240454827 25.3025157956859 0,55.350167476337 25.302052320791 0,55.3502179592688 25.3015310354212 0,55.3503440422899 25.3009514712837 0,55.3504486119223 25.3006301210427 0,55.3506041366917 25.3001971986575 0,55.3507407980781 25.2999378877706 0,55.3509409235735 25.2996194054772 0,55.3511597952159 25.29936341535 0,55.351438344097 25.299097325261 0,55.3517204846052 25.2988849274712 0,55.3519594145438 25.2987109991387 0,55.3522876456629 25.2985451382345 0,55.3525536744323 25.2984426640962 0,55.3528500690474 25.2983424512678 0,55.3531773557644 25.2983056491795 0,55.3534747914445 25.2982610690704 0,55.3540737142463 25.298234157475 0,55.354520970558 25.2982895926112 0,55.3549087989035 25.2983600652439 0,55.3554400989818 25.2984995277203 0,55.3559230774483 25.2987816873014 0,55.3563242005882 25.2990420485621 0,55.3566496864508 25.2992940074279 0,55.3570369833753 25.2996727865998 0,55.3573765715678 25.3001682840711 0,55.3575614648468 25.3004875879469 0,55.3576646516623 25.3007980494817 0,55.3577301294947 25.3010862563148 0,55.3577369577171 25.3014145712556 0,55.3577603142799 25.3018635578716 0,55.3576919912619 25.3021979965628 0,55.3576284663501 25.3024932928653 0,55.3575358155099 25.3027392065909 0,55.3572694247201 25.3030472370159 0,55.3567224538132 25.3035356823921 0,55.3564020957784 25.3037313593414 0,55.3561647308198 25.3039554130217 0,55.3557515132586 25.3042175785239 0,55.3555141042301 25.3043749659542 0,55.3552023171315 25.304543494473 0,55.3547742252012 25.3047811688792 0,55.3542685794734 25.3051658685415 0,55.3538810985146 25.3054561355193 0,55.3533080001369 25.305911550566 0,55.3527554398248 25.3064654193014 0,55.3524377263786 25.3068335139645 0,55.3519785319481 25.3073568198734 0,55.3515953425664 25.3078061648841 0,55.3513098403357 25.3083271992808 0,55.351115969008 25.3087214725099 0,55.3506536957939 25.3094729706606 0,55.350150171901 25.3094929066307 0,55.3501435187128 25.3093527255152 0,55.3497246755132 25.3093691568646 0,55.3497419347157 25.3097326583012 0,55.3505747275344 25.309699677535 0,55.3504177120256 25.3102118664877 0,55.3502453183348 25.310626121985 0,55.3498810158451 25.3105990639656 0,55.3498010338009 25.31127650266 0,55.3496890190129 25.3119978345632 0,55.349681346734 25.3120311363835 0,55.3496830258082 25.312036471213 0,55.3496544686997 25.312220338333 0,55.3496247006687 25.3124099107032 0,55.350621622568 25.3113877038376 0,55.3520911887437 25.3098890254371 0,55.352825956829 25.3091306535349 0,55.3550302110271 25.3068825967406 0,55.3557649426917 25.3061242189337 0,55.3564996686401 25.3053838735539 0,55.357234383892 25.3046345063646 0,55.3579591596616 25.3038851461309 0,55.3586938488498 25.3031447896151 0,55.3594285470413 25.302395411285 0,55.3620115572487 25.2997497169043 0,55.3623473517296 25.2994069007336 0,55.3620095037742 25.2984500836102 0,55.3616815910594 25.297493272703 0,55.3610059215519 25.2955796520432 0,55.3608269637513 25.2945957294727 0,55.3602901137154 25.2916710410271 0,55.3601012400685 25.290696145984 0,55.3599222868459 25.2897122216545 0,55.3597433583325 25.2887373240978 0,55.3594949149411 25.2877443842795 0,55.3592464775211 25.2867604710355 0,55.3589980322884 25.2857675301097 0,55.3587595417399 25.2847836140467 0,55.3575677338471 25.283068659268 0,55.356971844223 25.2822202052452 0,55.3557206130109 25.2810378455331 0,55.3554426960018 25.2814982804367 0,55.3540826877878 25.2827532407858 0,55.3519383800746 25.2847033876554 0,55.351015119284 25.2855701058748 0,55.3502606062617 25.2862020935571 0,55.3494961551625 25.2868250512888 0,55.3487316973927 25.28745703214 0,55.3479672306158 25.2880799818512 0,55.3471729714648 25.2887300117327 0,55.3456042845811 25.2900120026028 0,55.3454454334135 25.2901925582552 0,55.3453064395856 25.290364084996 0,55.34456178595 25.2909870152169 0,55.3438270732355 25.29160090477 0,55.3430923439167 25.2922238357936 0,55.3423576064209 25.2928377269573 0,55.3416228621395 25.2934606415344 0,55.3407888182601 25.2941557744242 0,55.3399646945822 25.2948509020886 0,55.3391306317358 25.2955460254755 0,55.3383064892035 25.2962411437476 0,55.3374724073888 25.2969362576297 0,55.3366482460008 25.2976313665078 0,55.3358141454002 25.2983354979997 0,55.3365291335775 25.2990395992765 0,55.3372540402673 25.2997436967559 0,55.3379690354371 25.3004568180298 0,55.3386939688051 25.3011609082938 0,55.3387238109945 25.302325404666 0,55.3387437233395 25.3034899012128 0,55.3392998786101 25.3043474551545 0,55.3398560223316 25.3052140340063 0,55.3404121833709 25.3060715835498 0,55.3414648660143 25.3066131556423 0,55.3414053232512 25.3072360292084 0,55.3405215353073 25.308021433065 0,55.3391213313238 25.3087978256156 0,55.3381566879015 25.3092889979292 0,55.3381042339874 25.3093156837519 0,55.3392098693289 25.3109494499612 0,55.339222922439 25.3110268748837 0,55.3392341686259 25.3111148074216 0,55.33924186943 25.3112024151241 0,55.3392460844606 25.3112903298865 0,55.3392468137018 25.311378380194 0,55.3392440372757 25.3114663945326 0,55.3392377650978 25.311554210414 0,55.3392280368761 25.3116416472941 0,55.3392148625262 25.3117285336569 0,55.3391981626229 25.3118155104289 0,55.339174362047 25.311904356089 0,55.3391465195422 25.3119946191583 0,55.3391151414785 25.3120840428397 0,55.339080257634 25.3121724556149 0,55.3390419375114 25.3122596769368 0,55.3390002406841 25.3123455533397 0,55.3389552763814 25.312429922329 0,55.3389165082418 25.3124965347655 0,55.3388692969681 25.3125277522539 0,55.3388421463 25.3125522076818 0,55.3388190377875 25.3125807793113 0,55.3388010141625 25.3126125643957 0,55.3387887904187 25.3126463893876 0,55.3387826346446 25.3126809724305 0,55.3387823779571 25.3127150136291 0,55.3387874542375 25.312747465861 0,55.3387973569944 25.312778202765 0,55.338812582843 25.3128084068717 0,55.3388333204394 25.3128371935167 0,55.3388593214534 25.3128633711301 0,55.3388899005822 25.3128857842662 0,55.3389239852163 25.3129035302531 0,55.3389602644101 25.3129160314042 0,55.3389973179924 25.3129231252846 0,55.3390337953273 25.3129250285965 0,55.3390689019386 25.3129222378614 0,55.3391040083255 25.3129147439998 0,55.3391388065978 25.3129021408042 0,55.3391720056941 25.3128843561092 0,55.339202235123 25.3128617059188 0,55.3392282535194 25.3128348943983 0,55.3392491274024 25.3128049416492 0,55.3392667532764 25.3127646259187 0,55.3393073922905 25.3127779663293 0,55.3393527587621 25.3127955402448 0,55.3393972514245 25.312815551499 0,55.3394406319282 25.3128379278855 0,55.3394826718541 25.3128625971981 0,55.339523162644 25.3128894601487 0,55.3395618957372 25.3129183813407 0,55.3395986824348 25.3129492253771 0,55.3396333538976 25.3129818117245 0,55.339665781011 25.3130159688752 0,55.3396958346592 25.3130515162942 0,55.3397234254492 25.3130882373364 0,55.3397491989532 25.3131269985766 0,55.3426990206762 25.3174708866424 0,55.3427298028259 25.3175260402201 0,55.3427598503493 25.3175848317562 0,55.3427875342712 25.3176446976615 0,55.3428127949897 25.3177055115616 0,55.3428355729031 25.3177671561094 0,55.3428558084086 25.3178295049306 0,55.3428734716973 25.3178924226219 0,55.3428885428931 25.3179557918331 0,55.342891454017 25.3179706502381 0,55.3428510632772 25.317984301815 0,55.3428232657537 25.3179974019179 0,55.34279721647 25.3180141578756 0,55.3427737397189 25.3180341995255 0,55.3427535704001 25.3180570303317 0,55.3427372249024 25.3180819371224 0,55.3427250110475 25.3181081435492 0,55.3427169784309 25.3181348100905 0,55.3427129581657 25.3181612597258 0,55.3427125926692 25.3181868786359 0,55.3427156535686 25.3182123438673 0,55.3427224487971 25.318238314378 0,55.3427332563951 25.3182641763072 0,55.3427481756242 25.3182891894265 0,55.3427670574508 25.3183125593598 0,55.3427895641413 25.3183335188247 0,55.3428150401604 25.3183514449923 0,55.3428427405965 25.3183658414192 0,55.342871781513 25.3183764554026 0,55.3429012789911 25.3183832689451 0,55.3429304385102 25.3183864445858 0,55.3429555953223 25.3183863165664 0,55.3429868896249 25.318382938388 0,55.34301383372 25.3183776557723 0,55.3430403406584 25.3183703330578 0,55.3430661323591 25.3183610424797 0,55.3430909406727 25.318349856273 0,55.343131529448 25.3183276108266 0,55.3431763896899 25.3183162878648 0,55.3432310820711 25.3183029872964 0,55.3432877706997 25.3182897226812 0,55.343381284538 25.3182615066746 0,55.343473010483 25.3182313860151 0,55.3435638522852 25.3181990808036 0,55.3436537106267 25.3181646181299 0,55.3437455052818 25.3181266527528 0,55.343807803569 25.318095225032 0,55.3438697440638 25.318061224589 0,55.3439304230251 25.3180250938168 0,55.343989701414 25.3179868959166 0,55.3440474501245 25.3179467031162 0,55.3441179101093 25.3178937992176 0,55.3442096400634 25.3180249109915 0,55.3443053843644 25.3181757556301 0,55.3443453481291 25.3182739674091 0,55.3443776646171 25.3183723332097 0,55.3443948658649 25.3184779759727 0,55.3444010741956 25.3185988753424 0,55.3443980556277 25.3187153701823 0,55.3443835920795 25.3187911627248 0,55.3443633075945 25.318856357896 0,55.3443355252025 25.3189274122057 0,55.3443022101764 25.3189911910861 0,55.3442567186734 25.3190527953323 0,55.3442014144578 25.3191126490322 0,55.344153516373 25.3191403205891 0,55.3441433752709 25.3191308158067 0,55.3441250993425 25.3191125914497 0,55.3440986197893 25.3190937448204 0,55.3440755372606 25.3190791948341 0,55.344048233857 25.3190656291039 0,55.3440231851028 25.3190537783524 0,55.3439977990003 25.3190456287282 0,55.3439705257069 25.3190354842488 0,55.3439330233696 25.319032065683 0,55.3438898204287 25.3190307327739 0,55.3438615845579 25.3190296515425 0,55.3438275590583 25.3190348626003 0,55.3438052830554 25.3190437558691 0,55.3437869297605 25.3190491012096 0,55.3437504519985 25.3190645130361 0,55.3437232110759 25.3190843655314 0,55.3436988005869 25.3191031706801 0,55.3436765055015 25.3191215152947 0,55.3436610335252 25.319140364945 0,55.343635382709 25.3191728281582 0,55.3436238544205 25.3192013455429 0,55.3436086218423 25.3192327067184 0,55.3436021975205 25.3192503551282 0,55.3435950984685 25.3192754509344 0,55.3435949528097 25.3193148090592 0,55.3435962797394 25.3193861500628 0,55.3439300065417 25.3203151042651 0,55.3441269952812 25.3212299763856 0,55.3441365232819 25.3212676637805 0,55.3441563794897 25.3212947435881 0,55.3441643064722 25.321309935595 0,55.3441947312614 25.3213488581597 0,55.3442247670997 25.3213695911644 0,55.3442545643428 25.3213876431355 0,55.3442647055849 25.3213965160112 0,55.3442972933187 25.3214103521165 0,55.344329424173 25.3214239625714 0,55.3443553469885 25.321430712897 0,55.3443855699495 25.3214334819497 0,55.3444179880875 25.3214387784159 0,55.3444509420256 25.3214383336066 0,55.3444888016391 25.3214305403691 0,55.3445211393503 25.3214252209633 0,55.3445434551931 25.3214133847554 0,55.344574372088 25.3214020985408 0,55.3446041660484 25.3213840420897 0,55.3446308910023 25.3213654622966 0,55.3446581717508 25.3213427751308 0,55.3446680029356 25.3213280692487 0,55.3446990861255 25.3212898551914 0,55.3447139219688 25.3212645240375 0,55.3447203257827 25.3212405746781 0,55.3447302551119 25.3212134926462 0,55.3447340079762 25.3211987601481 0,55.3447356635098 25.3211657930939 0,55.3447393259799 25.3211403273946 0,55.3447296980439 25.3210979369328 0,55.3447157202787 25.321058904883 0,55.3447094807716 25.3210342253051 0,55.3446896145514 25.3210071455719 0,55.3446755594091 25.3209901667008 0,55.3446556932036 25.3209630869628 0,55.3446263221055 25.3209345906977 0,55.3445766604095 25.3209075132288 0,55.3445682773269 25.3209008789579 0,55.3445546195695 25.3208847937265 0,55.3444647692168 25.3204825985973 0,55.3446397877346 25.3204858079466 0,55.3448217299323 25.3205017808525 0,55.3450176580156 25.3205370974775 0,55.3452063685032 25.3206002720197 0,55.3452465043554 25.3206145857442 0,55.3455023698669 25.3207354195067 0,55.3457172474679 25.3208587658031 0,55.3459311456926 25.3210153676614 0,55.3461371114004 25.3211956298931 0,55.3462546221057 25.3213539096273 0,55.3464256471458 25.3216141003407 0,55.3465660168528 25.3219088854001 0,55.3466733725489 25.3221953322773 0,55.3467024038081 25.3222875413391 0,55.346716227915 25.3223672853689 0,55.3467204663345 25.3224346451047 0,55.3467165612465 25.3225083787025 0,55.3467071817704 25.3225651238197 0,55.3466854302342 25.3226509733836 0,55.3466537455496 25.3227264788005 0,55.3466125055884 25.3227959188692 0,55.346572178144 25.3228545082862 0,55.3465265960476 25.3229076999648 0,55.3464658380562 25.3229631858617 0,55.3464079392618 25.3230078118952 0,55.3464092576749 25.3229841247047 0,55.3464168737096 25.3229672433781 0,55.3464267830021 25.3229407570278 0,55.3464351821415 25.322909766295 0,55.346436152495 25.3228820530545 0,55.3464361495806 25.3228549717965 0,55.3464344590791 25.3228358074429 0,55.3464272751252 25.3228067769723 0,55.3464188398692 25.3227789111063 0,55.3464089059399 25.3227608487885 0,55.3463922075164 25.3227351952898 0,55.3463730364478 25.3227133875467 0,55.3463579581653 25.3226990809482 0,55.3463381021558 25.3226805862017 0,55.3463127439297 25.3226629765916 0,55.3462865519577 25.3226503770833 0,55.3462650681428 25.3226414872897 0,55.3462352712514 25.3226324628147 0,55.3462033792031 25.3226280333037 0,55.3461736924025 25.322626889453 0,55.3461538284484 25.3226268911822 0,55.3461219270471 25.3226279320687 0,55.3460924792182 25.3226325474621 0,55.3460621479243 25.3226417847941 0,55.3460353724052 25.3226522765785 0,55.3460126791631 25.3226650518597 0,55.3459917638441 25.3226788199642 0,55.3459723982741 25.3226960994694 0,55.3459539663127 25.3227134511088 0,55.3459366569762 25.3227338538049 0,55.3459211948622 25.3227530828201 0,55.3459080973753 25.3227802374135 0,55.3458972643022 25.3228066696458 0,55.3458937105527 25.3228251213128 0,55.3458888561399 25.3228477345773 0,55.3458829711285 25.3228929607799 0,55.3460894714004 25.3238798833339 0,55.3462617618876 25.3247094573735 0,55.3462738431301 25.324744752211 0,55.3462783753868 25.324774812002 0,55.3462858072731 25.3247995906939 0,55.346293983903 25.324822762499 0,55.3463062921503 25.3248443993357 0,55.3463304305622 25.3248750080496 0,55.3463476349082 25.3248922572882 0,55.3463680379116 25.3249141371357 0,55.3463908240116 25.3249301401378 0,55.3464211688533 25.3249494644321 0,55.346450251656 25.3249626323614 0,55.3464772284719 25.3249723430998 0,55.3465087637777 25.3249785418903 0,55.3465405074243 25.324982547074 0,55.3465668776672 25.3249856139169 0,55.346597994866 25.324982966184 0,55.3466182065743 25.3249806173217 0,55.3466500981944 25.3249753606809 0,55.34669502953 25.3249589995387 0,55.3467185475811 25.3249469823564 0,55.3467471605072 25.3249320489587 0,55.3467733095599 25.3249108690383 0,55.3467978193835 25.3248859520504 0,55.3468121096608 25.3248669577601 0,55.3468319709766 25.3248398656642 0,55.3468446913093 25.324814985856 0,55.346854620457 25.3247879036942 0,55.3468592365023 25.3247662472967 0,55.3468638611457 25.3247326029309 0,55.3468658843028 25.3247056027374 0,55.3468658812925 25.3246785214861 0,55.3468593030105 25.3246496986111 0,55.3468492883145 25.3246218058406 0,55.3468393541728 25.3246037616105 0,55.3468268569234 25.3245801298494 0,55.3468031751047 25.3245475442424 0,55.3467688556565 25.3245119716368 0,55.3467500413167 25.324485803834 0,55.3467289222509 25.3244552671295 0,55.3467179451138 25.3244358237875 0,55.3466807968311 25.3242351550726 0,55.3469342250373 25.3242398982035 0,55.3471761731246 25.3242567743787 0,55.3474235678954 25.3243066526564 0,55.3476639825884 25.3243735111427 0,55.3478957395376 25.3244638224564 0,55.3481089753187 25.3245699416865 0,55.3483122922593 25.3247004437683 0,55.3483957100685 25.3247622346818 0,55.3484883671467 25.3248423315235 0,55.3485797134277 25.3249234394749 0,55.348657384556 25.3250150743706 0,55.3487342233322 25.3251212068069 0,55.3487918037243 25.3252273141417 0,55.3488380034232 25.3253452391018 0,55.34886816142 25.3254531727566 0,55.3488895529269 25.3255893079357 0,55.3488895563875 25.3256163891834 0,55.3488934292589 25.3256886595981 0,55.3488855739719 25.3257750496071 0,55.3488644196555 25.3258634179478 0,55.3488371559089 25.325943409795 0,55.3487978929418 25.3260153597657 0,55.3487564345983 25.3260849358324 0,55.3487005252682 25.3261585214188 0,55.3486526882349 25.3262116688309 0,55.3486472043276 25.3262013785275 0,55.3486422239188 25.3261668504563 0,55.3486311860248 25.326141810477 0,55.3486173973215 25.3261201378837 0,55.3486044831501 25.3261023558708 0,55.3485846152363 25.3260752766819 0,55.3485599803621 25.3260523053052 0,55.3485379191463 25.326038902366 0,55.3485128384152 25.3260245789721 0,55.3484882644306 25.326011826234 0,55.3484584665496 25.3260028022131 0,55.3484313505154 25.3259948611612 0,55.3483990601941 25.3259902516267 0,55.3483707332215 25.3259887018617 0,55.3483470151269 25.3259896882319 0,55.3483134841497 25.3259921560376 0,55.3482829634815 25.3260014480044 0,55.3482566937842 25.3260105048303 0,55.3482359959259 25.326018324378 0,55.3482061811146 25.3260331769402 0,55.348176684824 25.3260537345801 0,55.3481537836823 25.3260754379904 0,55.3481339213607 25.3260934941507 0,55.3481168211304 25.3261191959699 0,55.3481028497181 25.3261462334815 0,55.3480959987953 25.3261655250422 0,55.3480860698116 25.3261926072826 0,55.3480819912466 25.3262222977634 0,55.3480786576416 25.3262523311986 0,55.3480804288691 25.3262794303212 0,55.3480859146694 25.3263057076074 0,55.348092284654 25.3263337089775 0,55.3481043853906 25.3263602473856 0,55.3481217009247 25.326389610746 0,55.3481400686955 25.3264140903473 0,55.348155873318 25.3264334337946 0,55.3487279645828 25.3269159629136 0,55.3488191025979 25.326986039622 0,55.34887939735 25.3270290473146 0,55.3489660645966 25.3270883280138 0,55.3489997282439 25.3271111990618 0,55.349035338449 25.3271325623721 0,55.349079868996 25.3271622928248 0,55.3500450870962 25.3277595896803 0,55.3500721153134 25.3277753569215 0,55.3501226636221 25.3277923220815 0,55.3501566035092 25.3277987003563 0,55.350216476246 25.3278003996272 0,55.3502712412002 25.3277839098947 0,55.3503141063582 25.3277618969405 0,55.3503656989765 25.3277177395381 0,55.3503911706847 25.3276829281711 0,55.3504140885516 25.3276395413694 0,55.3504236666184 25.327591922411 0,55.3504199054141 25.3275437362928 0,55.3504062219648 25.3274969324674 0,55.3503840879086 25.3274631918037 0,55.3503593120502 25.3274308506393 0,55.350337130154 25.3274099735634 0,55.3502961269437 25.3273927636464 0,55.3502563949722 25.3273747230806 0,55.350206731901 25.327365710722 0,55.3501868659229 25.3273566768878 0,55.3501555663021 25.3273368118598 0,55.3502025458519 25.3272613942584 0,55.3502348201711 25.3272193694999 0,55.3502967766888 25.3271373874611 0,55.3503617748216 25.3270725835788 0,55.3504078348297 25.3270284990134 0,55.3504694588061 25.3269846744098 0,55.3505442426692 25.3269379866591 0,55.3505973068657 25.3269081188682 0,55.3506720547544 25.3268884671643 0,55.3508169742794 25.3268674079164 0,55.3509317711045 25.3268607412935 0,55.3510890423615 25.3268803743841 0,55.3511988876617 25.3269057813686 0,55.3513530837933 25.3269510514599 0,55.3514758344163 25.3269972911619 0,55.3515901737156 25.3270520172596 0,55.3516701058263 25.3270957435419 0,55.3517314241715 25.3271354460276 0,55.3518108705029 25.3271844441087 0,55.3519245198229 25.3272716404408 0,55.3519662118754 25.3273105418922 0,55.3520400598617 25.3273810069536 0,55.3522612164152 25.3276527028563 0,55.3522347667817 25.3276547192901 0,55.3521843401901 25.3276556104031 0,55.3521529935249 25.3276552804077 0,55.3520548609275 25.3276513029379 0,55.3519578698647 25.3276427756102 0,55.3519052073666 25.32763630984 0,55.351875408835 25.3276272865123 0,55.3517711988599 25.3276312985841 0,55.3516763941803 25.3276308861425 0,55.3516525238971 25.3276125370579 0,55.3516095737022 25.3275954360739 0,55.3515552219097 25.327583436788 0,55.3514886763937 25.327593085923 0,55.3514304164377 25.327615940629 0,55.3513896188688 25.3276473869536 0,55.3513711584858 25.3276738656402 0,55.3513478863266 25.3277371122098 0,55.351351977321 25.327796428652 0,55.3513769554118 25.3278506693189 0,55.351400956988 25.3278836152195 0,55.3514527901853 25.327923273844 0,55.3514986407701 25.3279405911653 0,55.3515481639234 25.3279416231665 0,55.3516247416709 25.3279340489884 0,55.3517209261047 25.3279272667084 0,55.3517868896471 25.3279431732045 0,55.353419903343 25.3279204912615 0,55.3535487454302 25.3279137484689 0,55.3536368343278 25.3279039690582 0,55.3537626927136 25.3278736928927 0,55.3538351658646 25.3278522705946 0,55.3539327169008 25.3278225578981 0,55.354057737197 25.3277710769869 0,55.3541431361569 25.3277142304571 0,55.3542174710502 25.3276614205506 0,55.3542893819283 25.3276060021248 0,55.3543464565135 25.327566491495 0,55.3543822854353 25.3275254041401 0,55.3544329306762 25.3274684089402 0,55.3544840120548 25.327406584172 0,55.354550355807 25.3273240219853 0,55.3545817530022 25.3272728790509 0,55.3546485526577 25.3271854872648 0,55.3546706206289 25.3271190808663 0,55.3547124023893 25.3270419835417 0,55.3547428771084 25.3269421666851 0,55.3547642855905 25.3268538335866 0,55.3547752594097 25.3267331308897 0,55.3547725324449 25.32664544222 0,55.3547393836211 25.3263926526519 0,55.3546440605652 25.3262057336603 0,55.3544448952237 25.3259565426484 0,55.3542470887029 25.3257493902883 0,55.3540484410103 25.3254979328533 0,55.3539277472675 25.3252190760989 0,55.3538649532696 25.32502637469 0,55.3538353795963 25.3248162192792 0,55.3538807820129 25.3244193011113 0,55.3538885985396 25.3243601545668 0,55.3538927000909 25.3241812642679 0,55.3539072786204 25.3239943022887 0,55.3538835677374 25.3238000788441 0,55.3538197489209 25.3235918057998 0,55.353761599081 25.3234282069809 0,55.3536322983848 25.3232172889432 0,55.3535110758916 25.3230246675828 0,55.3533642855019 25.3228721840186 0,55.3532937253372 25.3227917261474 0,55.353083039805 25.3226190122102 0,55.352927416342 25.3224997671174 0,55.3527784238712 25.3224185430719 0,55.3526890261866 25.3223553562066 0,55.3525896937928 25.3222741344656 0,55.3525002948925 25.322201929425 0,55.3523910322258 25.3221297268991 0,55.3523016335494 25.3220575217365 0,55.3522420321541 25.3219943397861 0,55.3522023059916 25.321940182355 0,55.3521824224359 25.3218769952894 0,55.3521625488327 25.3218138082193 0,55.3521526029697 25.3217235386167 0,55.3521724542054 25.3216422922941 0,55.3522697862623 25.321511161375 0,55.3524446012321 25.3214091056397 0,55.3526491193604 25.3212269845637 0,55.3527384874209 25.3211096206808 0,55.3528079930661 25.3210012864559 0,55.3528476945967 25.320901983234 0,55.3528675508222 25.3207936555431 0,55.3528873970806 25.3206853278492 0,55.3528774522219 25.3206040853705 0,55.3528575712292 25.3204957629403 0,55.352817835171 25.3203784160428 0,55.3527582186386 25.3202791259322 0,55.3526988413628 25.3201848457992 0,55.3526064884313 25.3200762168845 0,55.3523644081505 25.3199277166097 0,55.3521546179425 25.3198524034576 0,55.3517947615622 25.3197917869259 0,55.3517053704045 25.3197556897359 0,55.3514074007077 25.3196383744063 0,55.351149157158 25.3195120265859 0,55.3509703790829 25.319394695914 0,55.350821376601 25.3192773705206 0,55.3506922390787 25.3191690516728 0,55.3506028496748 25.3190697641764 0,55.350523382165 25.3189704844948 0,55.350463780663 25.318889238589 0,55.350503499714 25.3188350714223 0,55.3505034895315 25.3187628546957 0,55.3504736843828 25.3186906504631 0,55.3504041577291 25.3186545411398 0,55.3503445640289 25.3186274667558 0,55.3502949070329 25.3186364995694 0,55.3502353020894 25.318528181321 0,55.3501458911342 25.3183386226261 0,55.3500962131171 25.3181941948176 0,55.3500564643421 25.3180317116796 0,55.3500465278049 25.3179233877026 0,55.350026628701 25.3177338210217 0,55.3500166736265 25.3175623073931 0,55.3500067235239 25.3174269021301 0,55.3499868419018 25.3172914979863 0,55.349957027561 25.3171470678647 0,55.3499073514833 25.3170116670619 0,55.3498477415601 25.3168582131664 0,55.3497484033782 25.3166867094857 0,55.3496590005848 25.3165422859153 0,55.349539803597 25.3163978655663 0,55.3494802040123 25.3163166282607 0,55.3494007415959 25.3162353930963 0,55.3493113478365 25.3161541589649 0,55.3492120227539 25.3160729258485 0,55.3490233090661 25.3159465577059 0,55.3489041226492 25.3158743626139 0,55.3488147428599 25.3158202094598 0,55.3487750026631 25.3157841052492 0,55.3487551352532 25.31574799895 0,55.3487451981257 25.3157028645152 0,55.3487451912718 25.3156487019469 0,55.3487551112491 25.31555842996 0,55.3487650266367 25.3154320495914 0,55.3487749477263 25.3153508046957 0,55.3487848710931 25.3152876139889 0,55.3488146613903 25.3151792857188 0,55.3487848413171 25.3150529095099 0,55.3487947669466 25.315007772991 0,55.3488344877732 25.3149716604369 0,55.3488543424258 25.3149084686776 0,55.3488344716887 25.3148452810975 0,55.3487848092523 25.3148001598588 0,55.3487351514165 25.3147911289322 0,55.3487004191019 25.3147719048425 0,55.3485415989989 25.3144684122857 0,55.3483508540753 25.3141125566125 0,55.3482212983779 25.3136890093329 0,55.348144096398 25.3133506160481 0))
A12: 11 | B12: 369 | C12: Sector 3 | D12: AL QOUZ IND. FOURTH | E12: 48926 | F12: 4.6890569 | G12: =E12/F12 -> 10434.081 | H12: =VLOOKUP(A12,ref!$A$2:$C$220,2,0) -> POLYGON Z ((55.236699107624 25.1271930449148 0,55.2375424058716 25.1266429259666 0,55.238375787537 25.1260837684908 0,55.2392091616232 25.1255246062649 0,55.2400425212751 25.1249744666052 0,55.2408758802647 25.1244152948811 0,55.2417092316755 25.1238561184079 0,55.2425425688366 25.1233059645046 0,55.2433759051516 25.1227467785353 0,55.2442092338881 25.122187587818 0,55.2450425550464 25.1216283923531 0,55.2458758721166 25.1210782194689 0,55.2467091682644 25.1205190145048 0,55.24754246675 25.1199598048001 0,55.2483757514164 25.1194096176739 0,55.2477515567383 25.1187051270152 0,55.2471174736786 25.1180006279262 0,55.2464933131925 25.1172961318857 0,55.245235068729 25.1158871348972 0,55.2446109198452 25.1151826217563 0,55.2439768630259 25.1144781089928 0,55.2433527284938 25.1137735994884 0,55.2427286011118 25.1130690873098 0,55.2420945659708 25.1123645663567 0,55.241470452945 25.1116600487888 0,55.2408463470683 25.1109555285475 0,55.2402123336028 25.110250999407 0,55.2395882420805 25.1095464737779 0,55.2383301659134 25.1081374081507 0,55.2370721185645 25.1067283316677 0,55.236448062894 25.1060237925945 0,55.23582401437 25.1053192508498 0,55.2351900587106 25.1046146998737 0,55.234566024536 25.1039101527454 0,55.2333080708551 25.1024920164499 0,55.2330305935826 25.1023473915216 0,55.2322072706034 25.1028975005789 0,55.231383940266 25.1034476050021 0,55.2305606101152 25.1039886774519 0,55.2297372651217 25.1045387726067 0,55.2289139127696 25.1050888631265 0,55.2280905431445 25.1056389490037 0,55.2272671859894 25.1061890302592 0,55.2264438115609 25.1067391068715 0,55.2256204297734 25.1072891788473 0,55.2247970406267 25.1078392461863 0,55.2239736441207 25.1083893088881 0,55.2231502483459 25.1089303396217 0,55.2223268371816 25.1094803930491 0,55.2215034186577 25.1100304418382 0,55.220680002697 25.1105804769691 0,55.2198565595303 25.1111305255006 0,55.2190331189265 25.1116805603731 0,55.2182096709542 25.1122305996334 0,55.2188038830913 25.1129622646011 0,55.2193881956455 25.1136849012247 0,55.2199824218035 25.1144165704027 0,55.2205667399014 25.1151482296111 0,55.2211609801336 25.1158798939705 0,55.2217453121878 25.1166115484381 0,55.2223296593452 25.1173341732343 0,55.2229239206181 25.1180658303845 0,55.2235082735372 25.1187974777596 0,55.2241025488876 25.1195291300889 0,55.2246869237483 25.1202517454035 0,55.2252812230498 25.1209833929188 0,55.2258655939315 25.1217150308005 0,55.2264598973976 25.1224466734857 0,55.2270442921651 25.1231782976024 0,55.2276386174713 25.1239009171773 0,55.2282230261521 25.1246325455763 0,55.2288074417856 25.1253641716214 0,55.2294314978826 25.1261319323687 0,55.2300555617719 25.126899690434 0,55.2306697173135 25.1276674389487 0,55.231293789227 25.128444219 0,55.2319178764789 25.1292119690583 0,55.2325320551971 25.1299797096892 0,55.2333654822625 25.1294205807756 0,55.2341989017479 25.1288614471098 0,55.235032306429 25.1283113360026 0,55.2358657108163 25.1277521928343 0,55.236699107624 25.1271930449148 0))
A13: 12 | B13: 681 | C13: Sector 6 | D13: AL BARSHA SOUTH FOURTH | E13: 44363 | F13: 6.8031892 | G13: =E13/F13 -> 6520.9123 | H13: =VLOOKUP(A13,ref!$A$2:$C$220,2,0) -> POLYGON Z ((55.2108090325971 25.0765575928916 0,55.2113347718341 25.0761517850777 0,55.2118506045487 25.075736957942 0,55.2123565218839 25.0753221118724 0,55.2128723653559 25.0748892173487 0,55.2133683628051 25.0744653323358 0,55.2138643854225 25.0740324182746 0,55.214360403363 25.0735904751389 0,55.2148465146894 25.0731394950238 0,55.2153227107517 25.0726885053975 0,55.2154318345632 25.0725892909331 0,55.2156600192171 25.0723637874963 0,55.215917972442 25.0721021977271 0,55.2161858533811 25.0718225605709 0,55.2164339013107 25.0715519346823 0,55.2168307928087 25.0711008776202 0,55.2171582665543 25.0706858746837 0,55.2173865040095 25.070397176881 0,55.2176147488754 25.0700994513361 0,55.2178231781592 25.069792682626 0,55.2180316064026 25.0694859136069 0,55.2182400336057 25.0691791442787 0,55.2184286453959 25.0688633319233 0,55.2186172562164 25.0685475193114 0,55.2188058744614 25.0682226790641 0,55.2189746690707 25.0678978232925 0,55.2191434627868 25.0675729673117 0,55.2193023527002 25.0672390761297 0,55.2194513305096 25.0669051771578 0,55.2196003075082 25.0665712780187 0,55.2197393808352 25.0662283437483 0,55.2198685339115 25.0658944291376 0,55.2199877834676 25.0655514704217 0,55.2201070505483 25.0651995022713 0,55.2202163777662 25.0648565447968 0,55.2203158115176 25.0645045523043 0,55.2204053336868 25.0641525431619 0,55.2207136975958 25.0629250611509 0,55.2210220553196 25.0616975692478 0,55.2212508172251 25.0608040300493 0,55.2214696651097 25.0599104829143 0,55.2216984203998 25.0590169427885 0,55.221917261813 25.0581233947567 0,55.2221460104888 25.0572298537038 0,55.2223648454316 25.0563363047754 0,55.2225935874939 25.0554427627957 0,55.2228124159673 25.0545492129708 0,55.223041151417 25.0536556700643 0,55.2232599734218 25.0527621193432 0,55.2234887022598 25.0518685755102 0,55.2225079663167 25.0514706411502 0,55.2215371466942 25.0510727077742 0,55.2205663251025 25.0506837954545 0,55.2195856080852 25.0502858418021 0,55.2179909331439 25.0494089536133 0,55.2167429019516 25.0487760607628 0,55.2154948551571 25.0481521848063 0,55.21445482975 25.0476367848422 0,55.2134148042633 25.0471304230511 0,55.2123846526774 25.046669190032 0,55.2113445992429 25.0462079507609 0,55.2097992940091 25.0456198831357 0,55.2087987147579 25.0453391980446 0,55.207798149282 25.0450494788184 0,55.2067182572849 25.0448138497418 0,55.2056383787994 25.0445691854215 0,55.2045585046347 25.0443245132611 0,55.2035479530667 25.0441250308863 0,55.2025473141855 25.043925550369 0,55.2015466785733 25.0437260631204 0,55.2005460462305 25.0435265691404 0,55.1995454269521 25.0433180410268 0,55.1989795718819 25.0442563811285 0,55.1984137081742 25.0451947189206 0,55.1978379361887 25.046124017967 0,55.1973415819403 25.0469179762611 0,55.1968352916894 25.0477209510672 0,55.1963980820843 25.0487948098568 0,55.1959608448508 25.0498776945561 0,55.1955430161368 25.0513216918261 0,55.1952142065182 25.052910217818 0,55.1951231023145 25.0546162931703 0,55.1952112726236 25.0555281512181 0,55.1952895239145 25.0564399908596 0,55.1954966624439 25.0573248678468 0,55.1957037839237 25.0582187718261 0,55.1960397462224 25.0591127945859 0,55.1963658127265 25.0599977799773 0,55.1968699973571 25.0611356952481 0,55.1986704000795 25.0636554023014 0,55.2102436778246 25.0769272474451 0,55.2108090325971 25.0765575928916 0))
A14: 13 | B14: 324 | C14: Sector 3 | D14: AL KIFAF | E14: 3868 | F14: 0.79564597 | G14: =E14/F14 -> 4861.4587 | H14: =VLOOKUP(A14,ref!$A$2:$C$220,2,0) -> POLYGON Z ((55.2988618536778 25.237849569329 0,55.2997353843993 25.2373984110808 0,55.3006089086763 25.2369472476339 0,55.3014824165861 25.2364960699592 0,55.3023658651131 25.2360358800344 0,55.3032393699554 25.2355847009336 0,55.3041128683533 25.2351335166354 0,55.3049863603066 25.2346823271399 0,55.3048972595292 25.2337254274553 0,55.3038949324128 25.2334273337367 0,55.302902534884 25.2331292352556 0,55.3019002198545 25.2328221007961 0,55.3008979074735 25.2325239867252 0,55.299905524607 25.2322258680938 0,55.2989032245356 25.2319187132828 0,55.297900926892 25.231620578862 0,55.2968688290448 25.2313946478605 0,55.2958367521046 25.2311777278221 0,55.2947947443904 25.2309608160372 0,55.2937626777307 25.2307348633393 0,55.292730592049 25.2305179306226 0,55.2916885985776 25.230291960705 0,55.2906565302602 25.2300750135019 0,55.2896244656162 25.2298580590894 0,55.290199725609 25.2308692832932 0,55.2907452465022 25.2318082609386 0,55.2913007103488 25.2327472483153 0,55.2918065637203 25.233614002008 0,55.2923124341832 25.2344807538792 0,55.2928183118103 25.235347512953 0,55.2933241995657 25.2362052249576 0,55.2938400165059 25.2370719740087 0,55.2943459156733 25.2379387185474 0,55.2948518220097 25.2388054612607 0,55.2953577383205 25.2396631749623 0,55.296231294921 25.2392120375719 0,55.297104845077 25.2387608949814 0,55.2979783887885 25.2383097471912 0,55.2988618536778 25.237849569329 0))
